Workbook
Name AE_Ben_All: '[1]B-IV - All Else'!$Z$42:$AS$42
Name AE_CountCost: '[1]DB - Departments'!$F$11:$H$20
Name AE_DeptList: '[1]DB - Departments'!$B$47:$B$56
Name AE_DeptList_Code: '[1]DB - Departments'!$B$47:$C$56
Name AppGrowth: '[1]DB - Cert Growth'!$M$47:$AF$47
Name Assm_HWSWCost: [1]Assumptions!$B$20
Name Assm_ImpCont: [1]Assumptions!$B$22
Name Assm_PayInc: [1]Assumptions!$B$18
Name Assm_RetBon: '[1]C-V - Other Emp Costs'!$F$47
Name Assm_SevRate: '[1]C-V - Other Emp Costs'!$G$25
Name BA_Hourly: [2]Dashboard!$C$20
Name Ben_Input: '[1]Benefit Input'!$A$10:$Y$76
Name Ben_Prob: '[1]Benefit Probabilities'!$A$10:$CL$76
Name BT_Ben_Intfc: '[1]B-II - Bus Tech'!$AO$69:$CB$69
Name BT_Ben_ModSys: '[1]B-II - Bus Tech'!$AO$73:$CB$73
Name BT_Ben_PASSuppt: '[1]B-II - Bus Tech'!$AO$67:$CB$67
Name BT_Ben_SpnCntl: '[1]B-II - Bus Tech'!$AO$75:$CB$75
Name BT_Ben_TechRat: '[1]B-II - Bus Tech'!$AO$71:$CB$71
Name BT_DeptList: '[1]DB - Departments'!$B$11:$B$21
Name BT_DeptList_Code: '[1]DB - Departments'!$B$11:$C$21
Name BUS_COST_HOUR: [3]Assumptions!$E$9
Name CertGrowth: '[1]DB - Cert Growth'!$L$10:$BT$21
Name CertGrowth_Prod: '[1]DB - Cert Growth'!$L$10:$L$21
Name CertGrowth_YrSys: '[1]DB - Cert Growth'!$L$10:$BT$10
Name ClaimsGrowth: '[1]DB - Cert Growth'!$M$77:$AF$77
Name CO_Ben_Auto: '[1]B-III - Core Ops'!$AR$131:$BK$131
Name CO_Ben_Claims: '[1]B-III - Core Ops'!$AR$135:$BK$135
Name CO_Ben_CSInt: '[1]B-III - Core Ops'!$AR$133:$BK$133
Name CO_Ben_OneSys: '[1]B-III - Core Ops'!$AR$129:$BK$129
Name CO_Ben_OutAuto: '[1]B-III - Core Ops'!$AR$137:$BK$137
Name CO_Ben_PmtMeth: '[1]B-III - Core Ops'!$AR$139:$BK$139
Name CO_Ben_SelfSvc: '[1]B-III - Core Ops'!$AR$141:$BK$141
Name CO_Ben_SpnCntrl: '[1]B-III - Core Ops'!$AR$143:$BK$143
Name CO_DeptList: '[1]DB - Departments'!$B$23:$B$45
Name CO_DeptList_Code: '[1]DB - Departments'!$B$23:$C$45
Name CONTINGENCY: [3]Assumptions!$E$84
Name Cost_Input: '[1]Cost Input'!$A$11:$Y$66
Name Cost_Prob: '[1]Cost Probabilities'!$A$10:$CL$60
Name CSC_Gap_Imp: '[1]V - CSC'!$E$96:$X$96
Name CSC_Gap_Recur: '[1]V - CSC'!$E$89:$X$89
Name CSC_OneTime: '[1]V - CSC'!$E$52:$X$52
Name CSC_Recurring: '[1]V - CSC'!$E$13:$X$13
Name Dash_Best: OFFSET('[1]Dashboard Input'!$C$9,0,0,,COUNT('[1]Dashboard Input'!$C$9:$V$9))
Name Dash_Probable: OFFSET('[1]Dashboard Input'!$C$8,0,0,,COUNT('[1]Dashboard Input'!$C$8:$V$8))
Name Dash_Submitted: OFFSET('[1]Dashboard Input'!$C$6,0,0,,COUNT('[1]Dashboard Input'!$C$6:$V$6))
Name Dash_Worst: OFFSET('[1]Dashboard Input'!$C$7,0,0,,COUNT('[1]Dashboard Input'!$C$7:$V$7))
Name DISCOUNT: [3]Assumptions!$E$7
Name Discount_Rate: [4]Dashboard!$C$10
Name DiscRate: '[5]Benefit Summary'!$D$5
Name FIN_Consult: [2]Dashboard!$C$28
Name FIN_PMO: [2]Dashboard!$C$29
Name FIN_Training: [2]Dashboard!$C$27
Name FTE_AE_Total: '[1]B-IV - All Else'!$M$42
Name FTE_BT_Efcy: '[1]B-II - Bus Tech'!$AF$67
Name FTE_BT_Suppt: '[1]B-II - Bus Tech'!$I$67
Name FTE_CO_Efcy: '[1]B-III - Core Ops'!$AF$127
Name FTE_CO_SpanCntl: '[1]B-III - Core Ops'!$AH$127
Name Group_GR: [2]Dashboard!$C$13
Name Hours_Day: [2]Dashboard!$C$30
Name Hours_Yr: [2]Dashboard!$C$25

Sheet Overview
I1: Status | N1: Priority
A2: Tab | B2: E2E Process | C2: Level 1 | D2: Level 2 | E2: Level 3 | F2: Sheet | G2: SRE - Direct | H2: Requirements | I2: Open | J2: FIT | K2: FIT Customizing | L2: GAP | M2: GAP Customizing | N2: High | O2: Medium | P2: Low | Q2: Progress | R2: Comments
A3: 1 | B3: P2P | C3: 5 Ordering, Processing & Claims | D3: 5.2 Request Goods & Services | E3: 5.2.1 Create Purchase Requisition | F3: 2.1 | G3: Yes | H3: =SUM(Overview!I3:M3) -> 13 | I3: =COUNTIF('2.1'!$Q:$Q,I2) -> 1 | J3: =COUNTIF('2.1'!$Q:$Q,J2) -> 5 | K3: =COUNTIF('2.1'!$Q:$Q,K2) -> 2 | L3: =COUNTIF('2.1'!$Q:$Q,L2) -> 4 | M3: =COUNTIF('2.1'!$Q:$Q,M2) -> 1 | N3: =COUNTIF('2.1'!$P:$P,N2) -> 8 | O3: =COUNTIF('2.1'!$P:$P,O2) -> 3 | P3: =COUNTIF('2.1'!$P:$P,P2) -> 0
A4: 2 | B4: P2P | C4: 5 Ordering, Processing & Claims | D4: 5.2 Request Goods & Services | E4: 5.2.2 Release Purchase Requisition | F4: 2.2 | G4: Yes | H4: =SUM(Overview!I4:M4) -> 11 | I4: =COUNTIF('2.2'!$Q:$Q,I2) -> 1 | J4: =COUNTIF('2.2'!$Q:$Q,J2) -> 6 | K4: =COUNTIF('2.2'!$Q:$Q,K2) -> 0 | L4: =COUNTIF('2.2'!$Q:$Q,L2) -> 4 | M4: =COUNTIF('2.2'!$Q:$Q,M2) -> 0 | N4: =COUNTIF('2.2'!$P:$P,N2) -> 9 | O4: =COUNTIF('2.2'!$P:$P,O2) -> 1 | P4: =COUNTIF('2.2'!$P:$P,P2) -> 0
A5: 3 | B5: P2P | C5: 5 Ordering, Processing & Claims | D5: 5.3 Create / Place Purchase Order | E5: 5.3.1 Create Purchase Order / Order Change | F5: 3.1 | G5: Yes | H5: =SUM(I5:M5) -> 12 | I5: =COUNTIF('3.1'!$Q:$Q,I2) -> 2 | J5: =COUNTIF('3.1'!$Q:$Q,J2) -> 4 | K5: =COUNTIF('3.1'!$Q:$Q,K2) -> 2 | L5: =COUNTIF('3.1'!$Q:$Q,L2) -> 4 | M5: =COUNTIF('3.1'!$Q:$Q,M2) -> 0 | N5: =COUNTIF('3.1'!$P:$P,N2) -> 6 | O5: =COUNTIF('3.1'!$P:$P,O2) -> 5 | P5: =COUNTIF('3.1'!$P:$P,P2) -> 1
A6: 4 | B6: P2P | C6: 5 Ordering, Processing & Claims | D6: 5.3 Create / Place Purchase Order | E6: 5.3.2 Release Purchase Order | F6: 3.2 | G6: Yes | H6: =SUM(Overview!I6:M6) -> 30 | I6: =COUNTIF('3.2'!$Q:$Q,I2) -> 0 | J6: =COUNTIF('3.2'!$Q:$Q,J2) -> 10 | K6: =COUNTIF('3.2'!$Q:$Q,K2) -> 3 | L6: =COUNTIF('3.2'!$Q:$Q,L2) -> 15 | M6: =COUNTIF('3.2'!$Q:$Q,M2) -> 2 | N6: =COUNTIF('3.2'!$P:$P,N2) -> 18 | O6: =COUNTIF('3.2'!$P:$P,O2) -> 6 | P6: =COUNTIF('3.2'!$P:$P,P2) -> 5
A7: 5 | B7: P2P | C7: 5 Ordering, Processing & Claims | D7: 5.3 Create / Place Purchase Order | E7: 5.3.3 Share Purchase Order with Supplier | F7: 3.3 | G7: Yes | H7: =SUM(Overview!I7:M7) -> 12 | I7: =COUNTIF('3.3'!$Q:$Q,I2) -> 1 | J7: =COUNTIF('3.3'!$Q:$Q,J2) -> 2 | K7: =COUNTIF('3.3'!$Q:$Q,K2) -> 4 | L7: =COUNTIF('3.3'!$Q:$Q,L2) -> 4 | M7: =COUNTIF('3.3'!$Q:$Q,M2) -> 1 | N7: =COUNTIF('3.3'!$P:$P,N2) -> 9 | O7: =COUNTIF('3.3'!$P:$P,O2) -> 3 | P7: =COUNTIF('3.3'!$P:$P,P2) -> 0
A8: 6 | B8: P2P | C8: 5 Ordering, Processing & Claims | D8: 5.4 Manage Purchase Order | E8: 5.4.1 Manage Purchase Order Confirmation / Response | F8: 4.1 | G8: Yes | H8: =SUM(Overview!I8:M8) -> 7 | I8: =COUNTIF('4.1'!$Q:$Q,I2) -> 0 | J8: =COUNTIF('4.1'!$Q:$Q,J2) -> 4 | K8: =COUNTIF('4.1'!$Q:$Q,K2) -> 3 | L8: =COUNTIF('4.1'!$Q:$Q,L2) -> 0 | M8: =COUNTIF('4.1'!$Q:$Q,M2) -> 0 | N8: =COUNTIF('4.1'!$P:$P,N2) -> 1 | O8: =COUNTIF('4.1'!$P:$P,O2) -> 5 | P8: =COUNTIF('4.1'!$P:$P,P2) -> 1
A9: 7 | B9: P2P | C9: 5 Ordering, Processing & Claims | D9: 5.4 Manage Purchase Order | E9: 5.4.2 Monitor Purchase Order Status | F9: 4.2 | G9: Yes | H9: =SUM(Overview!I9:M9) -> 1 | I9: =COUNTIF('4.2'!$Q:$Q,I2) -> 0 | J9: =COUNTIF('4.2'!$Q:$Q,J2) -> 1 | K9: =COUNTIF('4.2'!$Q:$Q,K2) -> 0 | L9: =COUNTIF('4.2'!$Q:$Q,L2) -> 0 | M9: =COUNTIF('4.2'!$Q:$Q,M2) -> 0 | N9: =COUNTIF('4.2'!$P:$P,N2) -> 1 | O9: =COUNTIF('4.2'!$P:$P,O2) -> 0 | P9: =COUNTIF('4.2'!$P:$P,P2) -> 0
A10: 8 | B10: P2P | C10: 5 Ordering, Processing & Claims | D10: 5.5 Receive Goods & Services | E10: 5.5.3 Confirm Receipt of Goods & Services | F10: 5.3 | G10: No | H10: 0
A11: 9 | B11: P2P | C11: 5 Ordering, Processing & Claims | D11: 5.5 Receive Goods & Services | E11: 5.5.4 Fulfill Customs & Statutory Reporting | F11: 5.4 | G11: No | H11: 0
A12: 10 | B12: P2P | C12: 5 Ordering, Processing & Claims | D12: 5.6 Manage Quality & Returns | E12: 5.6.5 Manage Incidents, Returns & Remedies / Claims | F12: 6.5 | G12: No | H12: 0
A13: 11 | B13: P2P | F13: here
A14: 12 | B14: P2P | F14: here
H15: =SUM(H3:H14) -> 86 | I15: =SUM(I3:I14) -> 5 | J15: =SUM(J3:J14) -> 32 | K15: =SUM(K3:K14) -> 14 | L15: =SUM(L3:L14) -> 31 | M15: =SUM(M3:M14) -> 4 | N15: =SUM(N3:N14) -> 52 | O15: =SUM(O3:O14) -> 23 | P15: =SUM(P3:P14) -> 7 | Q15: =(H15-I15)/H15 -> 0.94186047
B18: Role definition
B19: Planning overview
A21: Incorporated Scenarios
A22: 1 | B22: Construction
A23: 2 | B23: OPEX-Service
A24: 3 | B24: NET Rent
A25: 4 | B25: Other

Sheet Status
A1: Status
A2: Open
A3: FIT | B3: Fit to SHERPA X Standard
A4: FIT Customizing | B4: Fit to existing SHERPA X standard, but minor customizing effort to set up basic settings for a new company code
A5: GAP Customizing | B5: Customizing needed to fulfill requirement
A6: GAP | B6: Development needed to fulfill new requirement. Approved Decision request from GF Transformation Management required
A7: N/A

Sheet Actions
A1: No | B1: Description | C1: Who | D1: Status
A2: 1
A3: 2
A4: 3
A5: 4
A6: 5
A7: 6
A8: 7
A9: 8
A10: 9
A11: 10

Sheet 2.1
A1: Requirement ID | B1: Workstream | C1: Team | D1: Polarion # | E1: Scenario | F1: Level 1 | G1: Level 2 | H1: Level 3 | I1: I as a (persona/ WHO) | J1: want to… (WHAT) | K1: Detailed Description | L1: so that… (WHY) | M1: Acceptance Criteria | N1: Notes | O1: ACN Comments | P1: Prio (DRAFT, TB FINALIZED) | Q1: Status | R1: Feature assignment | S1: Dependancy | T1: using application/3rd Party Tools/interface (HOW) | U1: Value Flow Items | V1: Master Data Items | W1: SAP Best Practice | X1: SAP Module - Core | Y1: SAP Module - Public Cloud | Z1: Functional Shift | AA1: Role, Rights & FIORI App relevance | AB1: Role in User Story | AC1: SAP Role Name | AD1: Siemens Role Name | AE1: SAP Transaction Code | AF1: Customizing Code/ ID | AG1: FIORI App ID | AH1: FIORI App Name | AI1: FIORI App Description | AJ1: FIORI App Catalog ID | AK1: Sandbox relevance | AL1: Sandbox relevance comment
A2: R-2.1.1 | H2: 5.2.1 Create Purchase Requisition_1 | I2: Requisitioner | J2: … start creating a PR by populating the required information for specific demand | K2: Req. starts creating a PR in respective system | L2: …PR can be released in S4 for further processing | M2: PR is created in S4 system and required fields are populated | Q2: FIT
A3: R-2.1.2 | H3: 5.2.1 Create Purchase Requisition_2 | I3: Requisitioner | J3: … get displayed supplier with R4B status only (if supplier is already known by the Requisitioner) | L3: … so that unqualified supplier cannot be chosen. | M3: 1.Create a PR. 2. Try to choose an unqualified supplier 3. Unqualified supplier should not be displayed | N3: 30.10-MAS: As per the email from Sven, the R4B status 16.10-MAS: Align with GF if this is already linked to the PR and PO. (Nazli or Uwe or Sven). From Source to Contract ( S2C) process | O3: What is R4B and how it is managed currently ? R4B is Ready for Business The control should come from the MDG. The system will raise messages based on the Supplier/BP status | P3: Medium | Q3: FIT
A4: R-2.1.3 | H4: 5.2.1 Create Purchase Requisition_3 | I4: Requisitioner | J4: ...order for different company codes in the same Purchasing Organisation | K4: It shall be possible to have PRs created for multiple organizations by the same user, althoug he is allocated in one spesicifc company code | L4: … I can process requisitions for different AREs within one backend. | M4: Requisitioner opens PR and can change company code/plant to desired company code/plant based on assigned authorizations. Follow on processes are based on the chosen company code/plant and not on user data | N4: 16.10-MAS: Purchasing Organization will be cross company code Porg (In Germany) + the Requisitioner should have the required Authorization to create PRs for many company codes (use Account Assignment). The POrg will be assigned to the Plants related to the germany company codes. No need to create a new Plant for Direct SRE. Plant "C300" will be use. No need to create new Company Code for Direct SRE. CoCode "3003" will be use. 15.10-MAS: Purchasing Organization will be created for SRE Direct Procurement | O4: From the Authorization point of view, the user could create PRs in many Company codes 2 Fields are Mandatory for that: - Purchasing Group - Plant --> Company Code What are the CoCode/Plants which will be in scope for the direct procurment from Germany ? - 426Q and the following 15 CoCodes | P4: High | Q4: FIT Customizing
A5: R-2.1.4 | H5: 5.2.1 Create Purchase Requisition_4 | I5: Requisitioner | J5: ... have prefilled fields | K5: Predefined fields: GR: no GR PG: Function PG GBS Invoice: Invoice required | L5: … so that quality and performance is increased. | M5: Prefilled fields, e.g. 1. GR: no GR for all SRE PRs/POs as a standard logic, instead confirmation of service delivery per workflow step 2. Purchasing Group 3. Delivery address | N5: 18.10-MAS: Default PGroup should be defined per each SAP User (from his defualt value settings or User Parameters) 16.10-MAS: There are many Account Assignments in T4Q system are we going to use them ? Check if the GR and Valuated GR checkbox are in User Parameters. Compination between the new Account Assignemnt and Item Category should be Checked --> Harish Could the default address be changed from the Plant to the Requisitioner ? 14.10-MAS: VIM Topics: Mari Kraus --> mari.kraus@siemens.com 08.10-MAS: Gergana will arrange a meeting with the VIM Team | O5: What does the PG mean ? --> Purchasing Group Defualt Values (2 Options) 1- User Parameters --> GUI 2- Defualt Values --> Fiori Apps (F1995 - Default Settings for Users) --> per user and doesn't include the GR checkbox GR and Inovice Receipt are controlled based on the Account Assignment and Item Category. Delivery Address will be by default copied from the Item line "PLant" and could be changed Service Confirmation --> is it active now in VIM ? Invoice Receiver in PR should confirm the Service Confirmation could be easly maintained via Service Entry Sheet | P5: High | Q5: GAP
A6: R-2.1.5 | H6: 5.2.1 Create Purchase Requisition_5 | I6: Requisitioner | J6: ... change prefilled data and add new data where mandratory and/or applicable . | L6: ...so that quality and performance is increased. | O6: Default values could be changed for most of the fields, unless it is not controlled by configuration --> Mainly for the Account Assignment and Item Category, which control (GR, GR Valuation, Invoice Receipt and GR-Based Invoice). There is no GL automatically determination, then the GL could be changed manually in the PO. | P6: High | Q6: FIT
A7: R-2.1.6 | H7: 5.2.1 Create Purchase Requisition_6 | I7: Requisitioner | J7: ... have the opportunity to create orders with multi-account assignment | L7: … so that services can be billed across multiple cost centers. | O7: Standard SAP behaviour. | P7: High | Q7: FIT
A8: R-2.1.7 | H8: 5.2.1 Create Purchase Requisition_7 | I8: Requisitioner | J8: ... to be able to upload attachements on header and line item level, that are stored in the S4 archiving system | L8: … so that services can be billed across multiple cost centers. | N8: 04.11-MAS: Header is not possible in SHERPAX, but Item is available 28.10-MAS: email from Markus G. "it is possible to transfer data up to 500MB. But the recommended size should not be more than 50MB". 16.10-MAS: The size of the attachement should be checked | P8: Medium | Q8: Open
A9: R-2.1.8 | H9: 5.2.1 Create Purchase Requisition_8 | I9: Requisitioner | J9: ... have the Invoice Receiver field prefilled with my GID and be able to change the prefilled invoice receiver field with a GID from SCD. Contact data of invoice receiver shall be visible on the PO Print out. | K9: Use fiels Invoice Receiver (see requirements on Z-filed "Contact person") | L9: … so that the real (technical) specialist will be visible on the PO Print out for the supplier and also he will receive the invoice in VIM | N9: Question: Check if the invoice recevier can be anyone in the company, or a user in S4P and VIM (Readsoft Successor) is required. | O9: Goods Recipient: EBKN-WEMPF For Multi-Account Assignments, multi-recipients will be available. Requisitioner: EBAN-AFNAM it is per PR line item | P9: High | Q9: GAP
A10: R-2.1.9 | H10: 5.2.1 Create Purchase Requisition_9 | I10: Requisitioner | J10: … want to be able to manually assign the required PO approvals in this step | L10: … so that I do not have to touch the PO at a later point again | O10: The user is not able to choose the Approvers of the PO in the PR creation Step PO Approver Determination will be based PO parameters (Doc Type, Company Code, POrg, PO Value) | P10: High | Q10: GAP
A11: R-2.1.10 | H11: 5.2.1 Create Purchase Requisition_10 | I11: System | J11: a budget check is run against the account assignment object to check if the planed PR volume is available in the budget | L11: … not assure than only PR aligned with the planed budget are created | M11: 1.Create a PR. 2. Try to purchase a volume bigger than the available in the buget 3. Error message occurs | N11: 18.10-MAS: Budget Control pre-requeste (Config and Master Data) should be checked on the Cost Center and WBS | O11: Depending on Controlling team, if there is a budget check on the Cost Center or WBS. Is the requiremen for a PR check through an approval process ? | P11: Medium | Q11: GAP Customizing
A12: R-2.1.11 | H12: 5.2.1 Create Purchase Requisition_11 | I12: Requisitioner/System | J12: finalize PR and check if required data is correct | K12: The PR must be completed by the requisitioner/system before PR processing can continue. | L12: …PR can be released in S4 for further processing | M12: PR enriched with information. Check if all required fields are populated | N12: 18.10-MAS: Functional Pgroup will be assigned in the PR. SAP will only check on the completion of the PR based on the Mandatory Fields. | O12: What are the required fields, Based on the SAP Standard 1- Material or Short Text are mandatory 2- Accounting Data are mandatory 3- Purchasing Org is not mandatory 4- Plant, Pgroup, Material Group are mandatory 5- Supplier nuber is not mandatory If the PGroups are defined per Buyer, then the requisitioner will assign each item to a buyer ? | Q12: FIT
A13: R-2.1.12 | H13: 5.2.1 Create Purchase Requisition_12 | I13: Process Owner | J13: I want to be able to replace a Requisitioner in case the user is not active/not applicable anymore | L13: to avoid that not active users are responsible for handling the PR and the creation/change of PO cannot be performed | O13: PR Creator --> Automatically Assigned Requisitioner --> Line Item --> Free Text and not assigned the User GID Recipent --> Line Item/Account Assignment --> Free Text and not assigned the User GID | P13: High | Q13: GAP
A14: R-2.1.13 | I14: Requisitioner | J14: want to prepare a catalogue based purchase requisition using punchout process for SRE Direct process | P14: High | Q14: FIT Customizing

Sheet 2.2
A1: Requirement ID | B1: Workstream | C1: Team | D1: Polarion # | E1: Scenario | F1: Level 1 | G1: Level 2 | H1: Level 3 | I1: I as a (persona/ WHO) | J1: want to… (WHAT) | K1: Detailed Description | L1: so that… (WHY) | M1: Acceptance Criteria | N1: Notes | O1: ACN Comment | P1: Prio (DRAFT, TB FINALIZED) | Q1: Status | R1: Feature assignment | S1: using application/3rd Party Tools/interface (HOW) | T1: Value Flow Items | U1: Master Data Items | V1: SAP Best Practice | W1: SAP Module - Core | X1: SAP Module - Public Cloud | Y1: Functional Shift | Z1: Role, Rights & FIORI App relevance | AA1: Role in User Story | AB1: SAP Role Name | AC1: Siemens Role Name | AD1: SAP Transaction Code | AE1: Customizing Code/ ID | AF1: FIORI App ID | AG1: FIORI App Name | AH1: FIORI App Description | AI1: FIORI App Catalog ID | AJ1: Sandbox relevance | AK1: Sandbox relevance comment
A2: R-2.2.1 | H2: 5.2.2 Release Purchase Requisition_1 | I2: Process Owner | J2: avoid PR approvals to the upmost extent (eg based on thresholds) | L2: so that processing time is minimized. | M2: 1. Based on detailed concept, expert approvwer to be looped in for Purchase Requsition Release or not | N2: 18.10-MAS: no need for purchase requisition approval process for SRE | O2: Expert: Is someone checking the PR data and make PR item: flexible WF has a review step + team and responsibility Management | Q2: FIT
A3: R-2.2.2 | H3: 5.2.1 Create Purchase Requisition_9 | I3: Process Owner | J3: … I do not want to have posting of goods receipt, but confirmation of service delivery per workflow step as a standard logic instead | N3: 18.10-MAS: Service Confirmation will be manage by VIM | O3: Service Confirmation --> Service Entry Sheet --> No need GR checkbox should be unchecked per line item. | P3: High | Q3: Open
A4: R-2.2.3 | H4: 5.2.2 Release Purchase Requisition_2 | I4: Expert | J4: I want to receive a notification of new PRs for approval in the system | L4: so that processing time is minimized. | M4: 1. Create a PR with expert approval step. 2. Expert receives notification. Based on detailed concept, expert approver to be looped in for Purchase Requsition Release or not | N4: This step is not required for Rel. 1410 ARE426q, however question to Sherpa X Team: Can the PR Expert Approver Step (optional) be customized based on local requirements eg. For other global Roll-outs? 21.10. G.P: it should be possible to customize this functionality on CoCo-levele | O4: To Marcus/Ajit: Who should we ask in SHERPAX Team, about the local requirement ? Standard Reports to check for the PRs without POS "F1048A - Process Purchase Requisitions" | Q4: N/A
A5: R-2.2.4 | H5: 5.2.2 Release Purchase Requisition_3 | I5: Purchaser | J5: I want to receive new PRs in my work overview (Notification via Email required) | L5: so that I can start processing the business demand. | M5: 1. PR is created. 2. Purchaser receives new PRs in their work overview. | O5: Standard SAP Reports or Fiori Apps. Standard SAP Report "ME5A" could be handelled via a Background job to run automatically. | P5: Medium | Q5: GAP
A6: R-2.2.5 | H6: 5.2.2 Release Purchase Requisition_4 | I6: Purchaser | J6: … that all PRs are automatically directed to a functional PGroup. | L6: so that PRs can be assigned to purchasers. | M6: One of the following combinations has to be selected for verification: 1. Create PR 2. Correct PGroup automatically determined according to the settings 3. Assigned purchaser(s) can see the PR in work overview | N6: All PRs are initially automatically directed to the functional GBS PGroup. GBS team then reroutes the PRs according to specific instructions (no technical set-up needed, to be manually organized and comunicated within SCM team) to personalized PR groups. | O6: The PR could be assigned to a Purchasing Group (GBS), but for the rerouting of the PR, are they changing the Purchasing Group ? What is the creitera to assign Purchasinhg Group to the PR ? | P6: High | Q6: GAP
A7: R-2.2.6 | H7: 5.2.2 Release Purchase Requisition_5 | I7: Purchaser | J7: I want to be able to reroute PRs to other Pgroups (either another functional Pgroup or personalized Pgroups) | L7: so that the requested demand are allocated to the correct purchaser | M7: 1. Open PR as a purchaser and add a line item to existing PR 2. Change Prgroup | O7: Change of Pgroup is possible in SAP Standard Fiori app: Redistribute Workload | P7: High | Q7: FIT
A8: R-2.2.7 | H8: 5.2.2 Release Purchase Requisition_6 | I8: Purchaser | J8: I want to be able to check the status of the PR and identify who is responsible for it now. | O8: Status/Item: Standard Status field is available Responsible: Purchasing Group/Item | P8: High | Q8: FIT
A9: R-2.2.8 | H9: 5.2.2 Release Purchase Requisition_7 | I9: Purchaser | J9: I want to add and delete line items | L9: so that the requested demand are allocated to the ESN | M9: 1. Open PR as a purchaser and add a line item to existing PR 2. Open PR and delete one line item | O9: Standard SAP behaviour. | P9: High | Q9: FIT
A10: R-2.2.9 | H10: 5.2.2 Release Purchase Requisition_8 | I10: Purchaser | J10: I want to be able to edit all data fields | L10: so that the quality of the PR is ensured. | M10: 1. Purchaser opens assigned PR. 2. Purchaser check all field if editable. | O10: Standard SAP behaviour. | P10: High | Q10: FIT
A11: R-2.2.10 | H11: 5.2.2 Release Purchase Requisition_9 | I11: Purchaser | J11: I want to get displayed supplier with R4B status only | L11: so that unqualified supplier cannot be chosen. | M11: 1.Create a PR. 2. Try to choose an unqualified supplier 3. Unqualified supplier should not be displayed | N11: G.P.: Create contact to Sven Stöber and IT Team | P11: High | Q11: FIT
A12: R-2.2.11 | H12: 5.2.2 Release Purchase Requisition_10 | I12: Purchaser | J12: I want to assign the PR back to the requisitioner in case of clarification incl. comment what is missing | L12: so that missing data can be filled. | M12: 1. The purchaser opens the PR. 2. Add comment and assign to requisitioner. 3. Requisitioner receives notification. 4. Requisitioner add required data and assigns back to purchaser. | O12: PR item: flexible WF has a rework request + Agent determination by BAdI for PR creator/requisitioner or SAP BTP will be used --< to be Analysed | P12: High | Q12: GAP
A13: R-2.2.12 | H13: 5.2.2 Release Purchase Requisition_11 | I13: Requisitioner | J13: I want to be notified when a PR I created is rejected | L13: so that I can initiate a clarification process, inform the business and po-tentially create a new / adjust rejected shopping basket. | M13: 1. PR rejected from expert 2. The requester receives a notification about rejection of the PR (push principle). | O13: Notification is available for if we activate the PR Flexible WF and using "My Purchase Requisitions" Note: Requisitioner/Creator should be a BP if "My Purchase Requisition" will be active. | P13: High | Q13: GAP

Sheet 3.1
A1: Requirement ID | B1: Workstream | C1: Team | D1: Polarion # | E1: Scenario | F1: Level 1 | G1: Level 2 | H1: Level 3 | I1: I as a (persona/ WHO) | J1: want to… (WHAT) | K1: Detailed Description | L1: so that… (WHY) | M1: Acceptance Criteria | N1: Notes | O1: ACN Comment | P1: Prio (DRAFT, TB FINALIZED) | Q1: Status | R1: Feature assignment | S1: using application/3rd Party Tools/interface (HOW) | T1: Value Flow Items | U1: Master Data Items | V1: SAP Best Practice | W1: SAP Module - Core | X1: SAP Module - Public Cloud | Y1: Functional Shift | Z1: Role, Rights & FIORI App relevance | AA1: Role in User Story | AB1: SAP Role Name | AC1: Siemens Role Name | AD1: SAP Transaction Code | AE1: Customizing Code/ ID | AF1: FIORI App ID | AG1: FIORI App Name | AH1: FIORI App Description | AI1: FIORI App Catalog ID | AJ1: Sandbox relevance | AK1: Sandbox relevance comment
A2: R-3.1.1 | H2: 5.3.1 Create Purchase Order / Order Change_1 | I2: Purchaser | J2: I want to be able to change PO fields to finalize input of data | L2: so that PO can be enriched with data | M2: 1. Create a PO. 2. Populate fields | O2: While converting PR to PO, fileds could be changed. Default values will be taken from PR. | P2: High | Q2: FIT
A3: R-3.1.2 | H3: 5.3.1 Create Purchase Order / Order Change_2 | I3: Purchaser | J3: I want to be able to able to upload big size attachements on header and line item level that are stored the standard archive system | L3: so that PO can be enriched with data | M3: 1. Create a PO. 2. Populate fields | N3: G.P: : to provide contact 28.10-MAS: email from Markus G. "it is possible to transfer data up to 500MB. But the recommended size should not be more than 50MB". | O3: Document Size should be checked. | P3: Medium | Q3: Open
A4: R-3.1.3 | H4: 5.3.1 Create Purchase Order / Order Change_3 | I4: Purchaser | J4: I want to be able to change payment terms which are provided / prefilled according to supplier master data | L4: so that data deviations can be handled easily. | M4: 1. Create a PO. 2. Check if payment terms and incoterms are prefilled according to entries in supplier master data. | O4: Payment terms will not be inserted in the PR. Default value from Supplier master could be changed. | P4: High | Q4: FIT
A5: R-3.1.4 | H5: 5.3.1 Create Purchase Order / Order Change_4 | I5: Purchaser | J5: I want that relevant data is replicated to the Siemens Data Cloud | L5: so that official Siemens PO/PVO reportings are supported. | M5: PO data is available in PO/PVO reportings. | O5: Marcus: xBT Data Management team is driving connection between S/4 and SDC under the Data Governance Framework. | P5: High | Q5: FIT
A6: R-3.1.5 | H6: 5.3.1 Create Purchase Order / Order Change_5 | I6: Purchaser | J6: have an overview of new POs to be created from the PR | L6: so that processing time is minimized. | M6: PO Overview of new POs to be created and not to copy PR number from previous step | O6: Do you mean a report for the PRs which have not been converted to POs ? If yes, Standard Reports are availbale. "F1048A - Process Purchase Requisitions" | P6: Medium | Q6: FIT
A7: R-3.1.6 | H7: 5.3.1 Create Purchase Order / Order Change_6 | I7: Purchaser | J7: ... to be able to forward a PO to an Expert Buyer for review and change of the PO | L7: so that a high quality of the PO is assured | M7: 1. Create a PO with expert approval step. 2. Expert receives notification. Based on orgnisational set-up, expert approver to be looped in for PO Release or not | O7: Flexible WF: you could forward it as an email or add a new optional step for Expert Review. | P7: High | Q7: FIT Customizing
A8: R-3.1.7 | H8: 5.3.1 Create Purchase Order / Order Change_7 | I8: Expert (Buyer) | J8: .. To receive an email with the respective PO work item to review | L8: so that processing time is minimized. | M8: 1. Create a PO with expert approval step. 2. Expert receives notification. Based on orgnisational set-up , expert approver to be looped in for PO Release or not | O8: Flexible WF: Notification will be sent by defualt in "My Inbox" Fiori App after creating the Purchase Order. Email option is also available. | P8: Low | Q8: FIT Customizing
A9: R-3.1.8 | H9: 5.3.1 Create Purchase Order / Order Change_8 | I9: Expert (Buyer) | J9: .. To be able to review, change all data, send back and/or confirm PO | L9: so that a high quality of the PO is assured | M9: 1. Create a PO with expert approval step. 2. Expert receives notification. Based on detailed concept, expert approver to be looped in for PO Release or not | O9: Change the PO fields is available by accessing the Purchase Order Change transaction and if the change will affect the Total PO price the workflow will be retriggerred. Send back for review is not available in the Flexible WF. | P9: High | Q9: GAP
A10: R-3.1.9 | H10: 5.3.1 Create Purchase Order / Order Change_9 | I10: Expert (Buyer) and/or Purchaser | J10: I want to get closed multiple POs via mass update final invoice flag | L10: so that the open POs in the system can be closed (fiscal year ending). | M10: 1. Provide a list of line item number PO number of e.g. POs, where PO final invoice flag to be set 2. User / admins with respective authorization conduct the mass up-date. 3. Check POs are updated correctly. | N10: TBD if this functionaliyt is required for SRE ARE426q and if yes, who will have the rights to üerform mass updates? | O10: F2593 - Mass Changes to Purchase Orders Authorization to be requested to buyers - Currently available only for "Emergency Access (IT)" | P10: Medium | Q10: GAP
A11: R-3.1.10 | H11: 5.3.1 Create Purchase Order / Order Change_11 | I11: Process Owner | J11: I want that purchaser will be actively notified when negative deviations between PO price and invoice price occurs (price is higher than a defined tolerance) | L11: so that the PO can be adjusted. | M11: 1. Create a PO. 2. Post the invoice with large deviations so that the price is higher than a defined tolerance. 3. Check if the purchaser receives a pus notification. | N11: TBD if this functionaliyt is required for SRE ARE426q | O11: VIM -- consulidated topic for VIM meeting Tolerance will be configured in SAP. | P11: Medium | Q11: Open
A12: R-3.1.11 | H12: 5.3.1 Create Purchase Order / Order Change_13 | I12: Purchaser | J12: I want to have the possibility to update multiple POs via a mass update option without approval required | L12: so that reorganizations of data can be updated, e.g. accounting el-ements, G/L accounts. | M12: 1. Create multiple Pos. 2. Provide a list of POs and data fields which should be updated, e.g. PO old G/L account à G/L account PO old accounting element to new element 3. Execute mass update. 4. Check if changes are displayed in the POs. | N12: TBD if this functionaliyt is required for SRE ARE426q | O12: Is possible, If the changed field is not subject of Workflow reset. F2593 - Mass Changes to Purchase Orders Authorization to be requested to buyers - Currently available only for "Emergency Access (IT)" | P12: Medium | Q12: GAP
A13: R-3.1.12 | H13: 5.3.1 Create Purchase Order / Order Change_14 | I13: Process Owner | J13: I want to be able to replace a Requisitioner in case the user is not active/not applicable anymore | L13: to avoid that not active users are responsible for handling the PO and the creation/change of PO cannot be performed | N13: TBD if this functionaliyt is required for SRE ARE426q | O13: Requisitioner filed is a free text filed and could be changed. To have more control on this field additional logic should be performed. Initialy the Requisitioner should be the PR creator, but could be changed Requisitioner is on item level and the first line item will be the main requisitioner for the whole PR --> a logic to check the active user | P13: High | Q13: GAP

Sheet 3.2
A1: Requirement ID | B1: Workstream | C1: Team | D1: Polarion # | E1: Scenario | F1: Level 1 | G1: Level 2 | H1: Level 3 | I1: I as a (persona/ WHO) | J1: want to… (WHAT) | K1: Detailed Description | L1: so that… (WHY) | M1: Acceptance Criteria | N1: Notes | O1: ACN Comment | P1: Prio (DRAFT, TB FINALIZED) | Q1: Status | R1: Feature assignment | S1: using application/3rd Party Tools/interface (HOW) | T1: Value Flow Items | U1: Master Data Items | V1: SAP Best Practice | W1: SAP Module - Core | X1: SAP Module - Public Cloud | Y1: Functional Shift | Z1: Role, Rights & FIORI App relevance | AA1: Role in User Story | AB1: SAP Role Name | AC1: Siemens Role Name | AD1: SAP Transaction Code | AE1: Customizing Code/ ID | AF1: FIORI App ID | AG1: FIORI App Name | AH1: FIORI App Description | AI1: FIORI App Catalog ID | AJ1: Sandbox relevance | AK1: Sandbox relevance comment
A2: R-3.2.1 | H2: 5.3.2 Release Purchase Order_1 | I2: System | J2: … want to route the PO to the required PO approvals based on the choice provided by the Requisitioner in the PR creation step. | L2: so that the PR is not send again back to the Requisitioner | O2: The approver selection will be based on the information which have been copied from the PR, and if the Purchaser changed it. Purchasing Organization Purchasing Group | P2: High | Q2: GAP
A3: R-3.2.2 | H3: 5.3.2 Release Purchase Order_1 | I3: PO Approver | J3: I want to receive an email when new POs for approval arise | L3: so that I do not have to check proactively the system for new POs. | M3: 1. Create PO where an expert approval is required. 2. Check if PO expert receives a push notification for PO approval. | O3: Flexible WF: Notification will be sent by defualt in "My Inbox" Fiori App. Email option is also available. | P3: High | Q3: FIT Customizing
A4: R-3.2.3 | H4: 5.3.2 Release Purchase Order_2 | I4: PO Approver | J4: I want to edit relevant data fields in the PO, if required | L4: so that I can send the PO for approval and further processing is ensured. | M4: 1. Open the PO in the expert work overview. 2. Check if relevant data fields are editable. 3. Approve the PO. | O4: Changes will not be through "My Inbox" app. If the approver has access the Purchase Order Change transaction authorization, then he could perform the changes. | P4: Medium | Q4: FIT
A5: R-3.2.4 | H5: 5.3.2 Release Purchase Order_15 | I5: PO Approver | J5: I want to able to maintain substitutes | O5: Available in "My Inbox" Fiori app. Authorization for the substitute is required. | P5: High | Q5: FIT
A6: R-3.2.5 | H6: 5.3.2 Release Purchase Order_17 | I6: PO Approver | J6: I want to approve via smartphone, tablet or computer and all necessary data for decision are provided | L6: so that I can minimize the processing time. | M6: 1. Create multiple POs. 2. Check the opportunity for approval for tablet, computer and smartphone. 3. All relevant data are correctly displayed for decision. 4. Check if the POs can be approved and rejected via smartphone, tablet or computer. | O6: Not available for the Procureemnt Process in SHERPAX but could be activated | P6: Low | Q6: GAP
A7: R-3.2.6 | H7: 5.3.2 Release Purchase Order_19 | I7: PO Approver | J7: I want that the entire PO is rejected if an approver rejects the PO | L7: so that a PO is processed as a whole. | M7: 1. Create a PO with multiple approvers. 2. One approver rejects the PO. 3. Check if the PO has status “rejected”. 4. Check if work items from other approvers disappears. | O7: Standard SAP behaviour. PO is approved on Header Level. | P7: Medium | Q7: FIT
A8: R-3.2.7 | H8: 5.3.2 Release Purchase Order_21 | I8: PO Approver | J8: I want to approve all line items in a PO (which are assigned to me) with one click | K8: Use case 1: A PO with different accounting types, one cost center line item 1 - asset - cost center 1 and line item 2 - cost center - cost center 1 Use case 2: different cost centers, one approver line item 1 - cost center 1 - approver 1 and line item 2 - cost center 2 - approver 1 | L8: so that processing time in minimized | M8: 1. Create a PO with the following data Use case 1: A PO with different accounting types, one cost center line item 1 - asset - cost center 1 and line item 2 - cost center - cost center 1 Use case 2: different cost centers same approver line item 1 - cost center 1 - approver 1 and line item 2 - cost center 2 - approver 1 2. Check if the approver is correctly assigned. 3. Check if the approver can approve all item with one click. | N8: TBD if ARE426Q has the use case of multiple PO approvers | O8: Standard SAP behaviour. PO is entirelly approved on Header Level. Flexible WF: Starting Condition currently for Cost Center or Project - With SAT interface only one cost center will be sent to SAT to get the approvers --> in Buzias, the cost center in the first line item is selected. | P8: Medium | Q8: GAP
A9: R-3.2.8 | H9: 5.3.2 Release Purchase Order_3 | I9: Asset Expert | J9: I want to be involved in the PO expert verification step in case of - usage of the asset accounting type - or when the price per unit for goods is above a defined threshold | L9: so that the correctness of the asset process is ensured. | M9: 1. Create a PO with asset accounting type. 2. Asset expert involved in expert verification step. 1. Create a PO for goods with unit price above defined threshold. 2. Asset expert involved in expert verification step.G57 | N9: TBD Asset creation process for ARE426Q to be checked with dimitrios.chortikoglou@siemens.com G.P.: Fixed asset process is not required for ARE 426Q. Catalogue items should be ordered through Punch out process | O9: Asset Account Assignment is not an option in the Flexible WF starting Condition. Price Threshold could be defined in the Flexible WF starting Condition. | Q9: N/A
A10: R-3.2.9 | H10: 5.3.2 Release Purchase Order_4 | I10: Asset Expert | J10: I want to be able to edit accounting elements and asset master data | L10: so that the correctness of the asset process is ensured. | M10: 1. Create a PO with asset accounting type. 2. Asset expert involved in expert verification step. 3. Asset expert can edit the PO. 1. Create a PO for goods with unit price above defined threshold. 2. Asset expert involved in expert verification step. 3. Asset expert can edit the PO. | N10: TBD Asset creation process for ARE426Q to be checked with dimitrios.chortikoglou@siemens.com G.P.: Fixed asset process is not required for ARE 426Q. Catalogue items should be ordered through Punch out process | O10: Account Assignment could be chnaged during the approval process. | Q10: N/A
A11: R-3.2.10 | H11: 5.3.2 Release Purchase Order_5 | I11: Purchaser | J11: I want the system to check if the delivery date is in the past before final approval. Send back PO to Purchaser if delivery date is in the past. | L11: so that supplier receives the correct delivery date. | M11: 1. Create a PO. 2. Before final approval check if delivery date is in the past | O11: Delivery Date checking required opening the PO to check the messages. Approver could share any information from "My Inbox" app with the requisitioner. | P11: Low | Q11: GAP
A12: R-3.2.11 | H12: 5.3.2 Release Purchase Order_6 | I12: Purchaser | J12: I want that the language of the PO printout corresponds to the language of supplier master data (If language not applicable: use English as default) | L12: so that miscommunication towards the supplier can be avoided. | M12: 1. Create POs for several suppliers with different languages. 2. Check if the PO printout language is the correct supplier language. | O12: SHERPAX template follow the same. Predefined texts should include the vendor language. The Vendor Language in the PO will be the main driver, and it will be defualted from the vendor master. | P12: High | Q12: FIT
A13: R-3.2.12 | H13: 5.3.2 Release Purchase Order_7 | I13: Purchaser | J13: I want to have copy stored in the system of the PO printout as soon as it is created for legal aspects | L13: so that a copy of for legal purposes is stored in the system. | M13: 1. Create a PO. 2. Check if a copy of the PO printout is stored as attachment in the system. 3. Create a supplier relevant PO change. 4. Check if the PO change is stored as attachment in the system. | O13: All print out will be saved and attached to the PO. | P13: High | Q13: FIT
A14: R-3.2.13 | H14: 5.3.2 Release Purchase Order_8 | I14: Purchaser | J14: I want to rename the PO printout from “Order” to “Order Change” in case adjustments in the PO are required | L14: so that miscommunication towards the supplier can be avoided. | M14: 1. Create PO 2. Change in PO supplier relevant data 3. Check printout if “Order Change” is visible 4. Check printout if all line items are visible | O14: NB: (1) New --> Purchase Order (2) Change --> Change To FO: (1) New --> Framework Order (2) Change --> Change To | P14: High | Q14: FIT
A15: R-3.2.14 | H15: 5.3.2 Release Purchase Order_8 | I15: Purchaser | J15: I want to rename the PO printout from “Order” to “Order information” in case this is not a binding PO | L15: so that miscommunication towards the supplier can be avoided. | M15: 1. Create PO 2. Change in PO supplier relevant data 3. Check printout if “Order information” is visible 4. Check printout if all line items are visible | N15: TBD if PO Type Framework + item cat. B (Limit) can be set per default as Order Information, meaning not binding PO. | O15: Binding PO --> without specific Service in the line item, but only limit. What if the PO has many line item, one with limit and the other with Service. --> not a case Printout Form Titel is based on the Document type. | P15: High | Q15: GAP
A16: R-3.2.15 | H16: 5.3.2 Release Purchase Order_9 | I16: Purchaser | J16: I want that PO printout form contains automated texts and these be adjusted based on local (legal) requirements | L16: so that local (legal) regulations are fulfilled. | M16: 1. Create PO for different legal entities and languages 2. Check if content is correctly displayed | O16: Text changes are based on Company Code Purchasing Org Purchasing Group Order Type | P16: High | Q16: GAP
A17: R-3.2.16 | H17: 5.3.2 Release Purchase Order_10 | I17: Purchaser | J17: I want that PO is transferred according to the output media setting in the PO (prefilled from supplier master data) | L17: so that the PO is transferred as agreed with the supplier. | M17: 1. Create several POs with different output media settings - EDI (Classic EDI, SupplyON, or other future platforms) - Email - Fax (roll-In activity) - No output, if transfer is suppressed 2. Check if the PO transfer to the supplier worked correctly. | O17: It will be based on the Printout Condition Records Printout Condition type: "Y005" | P17: High | Q17: FIT Customizing
A18: R-3.2.17 | H18: 5.3.2 Release Purchase Order_11 | I18: Purchaser | J18: I want to decide if a PO change should be sent to supplier | L18: so that the supplier receives only a “PO Change” document if changed data fields are relevant for them. | M18: 1. Create a PO. 2. Change the PO. 3. Mark the PO “to be sent to the supplier” 4. Check if the PO is sent to the supplier 5. Mark the PO “not be sent to supplier” 6. Check if the PO is not sent to supplier | N18: G.P to merge the two requirements R-3.2.17 and R-3.2.18, this requirement will be only for sending or not sending the PO to supplier | O18: Is this a current functionality ? If, yes. How do you manage it ? Changes will be on assigned messages to the PO and the change will be manually per each PO. | P18: High | Q18: FIT
A19: R-3.2.18 | H19: 5.3.2 Release Purchase Order_12 | I19: Purchaser | J19: I want to select an alternative email to whom the Po should be sent | L19: so that POs for internal purposes are not sent to the supplier. | M19: 1. Create a PO. 2. Mark the PO „not to be sent“. 3. Check if the PO is not sent to the supplier. | N19: 04.11-MAS: Add another requirement to send the PO only to a buyer , R-3.2.18 could be used | P19: High | Q19: GAP Customizing
A20: R-3.2.19 | H20: 5.3.2 Release Purchase Order_13 | I20: Purchaser | J20: I want Requisitioner to receive a copy of a PO when a PO is sent to supplier via EDI or email | L20: so that Requisitioner knows the PO is sent to supplier (Requisitioner wants to have a copy of PO) | M20: Copy Requisitioner when Purchaser emails the PO to supplier | O20: Requisitioner field is a free text --> From where should we got the contact email. | P20: Low | Q20: GAP
A21: R-3.2.20 | H21: 5.3.2 Release Purchase Order_14 | I21: Purchaser | J21: PO is approved according the Siemens regulations and Sherpa X Standard | L21: so that the PO Approver is automatically addressed (if required) | M21: Interface with SAT is required | O21: Interface should be used with the Flexible WF to get the Authorized person for approval based on the PO Value Limit. SAT is based on 10 levels and Company Code Cost Center Profit Center Approval level Role (Functional and Commercial) Current interface logic for Buzias has been build with 2 levels Below 50K and Above 50K If the flexible WF will be only 2 levels approval (Functional and Commercial) with 50K thr | P21: High | Q21: GAP
A22: R-3.2.21 | H22: 5.3.2 Release Purchase Order_15 | I22: Purchaser | J22: I want to edit rejected POs | L22: so that I can avoid creating a new PO. | M22: 1. Create a PO. 2. Reject a PO. 3. The purchaser opens a rejected PO and edits the PO. 4. The PO is sent for approval (again). | O22: Available in SHERPAX, Change the rejected PO and then the Flexible WF will be retriggered. | P22: High | Q22: FIT
A23: R-3.2.22 | H23: 5.3.2 Release Purchase Order_16 | I23: Purchaser | J23: I want that only approvers with an activated user account approve POs | L23: so that the identity of user was verified. | M23: 1. Create a PO where an approver without active user account has to approve. 2. Check if the approver cannot access and approve. | O23: In Flexible WF, it will be defined by the SAP User ID and if the approver has and SAP ID then he/she is active. Additional checks on User profile (if he didn't access SAP for a long time or he is not a Siemens Employee) then it will be a gap. | P23: Low | Q23: GAP
A24: R-3.2.23 | H24: 5.3.2 Release Purchase Order_17 | I24: Purchaser | J24: I want to edit POs which are currently in the approval step | L24: so that I can correct errors without restarting the process. | M24: 1. Create a PO and start the approval step. 2. The purchaser calls and edits the PO. 3. During the “PO edit mode” the work item for approval should disappear in the approval step. 4. After editing the PO, the PO is again in the approval step. | O24: PO could be changed in approval process, only Total price could restart the workflow Standard fields which could be added: Header level attributes: Company Code Purchasing Group Purchasing Organization Total Net Order Value --> already selected Incoterms Currency Item level attributes: Material Group Outline Agreement Plant | P24: Medium | Q24: FIT
A25: R-3.2.24 | H25: 5.3.2 Release Purchase Order_18 | I25: Requisitioner | J25: I want to receive a push notification with a comment if the respective PO of my PR is rejected | L25: so that process time is minimized. | M25: 1. Create a PO. 2. Reject a PO with reason for rejection (reason is mandatory). 3. Check if requisitioner receives a notification incl. reason for rejection. | O25: GUI/Fiori reports could be used. Notifications to be checked | P25: Low | Q25: GAP
A26: R-3.2.25 | H26: 5.3.2 Release Purchase Order_19 | I26: Requisitioner | J26: I want that possible PO approvers are determined automatically | N26: TBD - Create approval matrix per ESN, PO value and Cost center logic | O26: PO Approvers will be determined automatically in the background. Cost Center is not in the Responsibility Definition. PO value will controlle the Flexible WF or SAT | P26: High | Q26: GAP
A27: R-3.2.26 | H27: 5.3.2 Release Purchase Order_20 | I27: Process owner | J27: I want that the next level of approver applies in case of no determination of an approver in a lower range of value I want that the workflow responsible gets notified in case no approver is determined | L27: so that processing time for approvals can be minimized. | M27: 1. Create a PO where the value range is not maintained. 2. Check if the next approval level applies. 3. Create a PO where no approver is maintained (e.g. new cost cen-ters) 4. Check if the workflow responsible gets notified. | N27: 28.10-MAS: changes will be on Buzias approval enhancement | O27: Value Levels: This will be based on SAT interface Approval Steps: Functional and Commercial both should be approved Workflow Admin should monitor the WF steps and redirect the WF-Steps without an approver assigned | P27: High | Q27: GAP
A28: R-3.2.27 | H28: 5.3.2 Release Purchase Order_21 | I28: As a requisitioner and approver | J28: we want get notified on a regular basis, if a PO is not approved in a specific time frame | L28: so that processing time can be minimized. | M28: 1. Create a PO with status “in approval”. 2. Wait until the time frame set is overdue (x days). 3. Check if a LoA approver receives a reminder notification. | N28: 28.10-MAS: for the Approver is required but for requisitioner is a nice to have. SRE will use the standard template without changes. | O28: Flexible WF: Deadline config Will appear in "My Inbox" and "Manage Purchase Order" apps | P28: Medium | Q28: GAP Customizing
A29: R-3.2.28 | H29: 5.3.2 Release Purchase Order_22 | I29: As a requisitioner, purchaser and approver, | J29: we want to be able to add “adhoc” approvers manually in the approval process, | L29: so that approvers required can be involved. | M29: 1. Valid maybe also for PR 2. Challenge how could a requisitioner do this? 3. Only user with respective authorizations should available as adhoc approvers | O29: Flexible WF: approvers are automatically determined without any additional approvers added Substitution or Forward options could be used Not Standard in SAP to have an adhoc approving step | P29: High | Q29: GAP
A30: R-3.2.29 | H30: 5.3.2 Release Purchase Order_23 | I30: As a requisitioner, purchaser and approver, | J30: we want to be able to replace approvers manually in approval process, according to LoA authorizations a) If no approvers could be determined a fallback or dummy ap-prover should be chosen b) Existing approver is currently not available | L30: so that approval process can be fastened. | M30: 1. Search for a PO. 2. Open the PO and replace the existing approver. | N30: 28.10-MAS: Team and Responsibility management will be used to limit the approvers based on their responsibility and it will work in the backgroung. Cost Center and WBS are not in the standard Responsibility definition. | O30: Substitute option could be perfomred per each approver BP is required per each approver | Q30: GAP
A31: R-3.2.30 | H31: 5.3.2 Release Purchase Order_24 | I31: As a requisitioner, purchaser and approver, | J31: we want to be able to replace approvers manually in approval process, according to LoA authorizations a) If no approvers could be determined a fallback or dummy ap-prover should be chosen b) Existing approver is currently not available | L31: so that approval process can be fastened. | M31: 1. Search for a PO. 2. Open the PO and replace the existing approver. | O31: Duplicate with the above | Q31: N/A
A32: R-3.2.31 | H32: 5.3.2 Release Purchase Order_25 | I32: Process owner | J32: I want to ensure that same PO approver cannot perform two approvals for one PO | K32: Commercial and technical PO approvers should be different people | L32: so that the approval is according to regulations. | M32: 1. Create PO with two LoA approval steps. 2. Determine one approver for two approval steps. 3. An error message appears. | O32: Controlled by approver determination logic + Teams Fucntion/Role If SAT is added, then additional logic should be added to do this check | P32: High | Q32: GAP
A33: R-3.2.32 | H33: 5.3.2 Release Purchase Order_26 | I33: Process owner | J33: I want only defined changes need an approval | L33: so that time is not wasted on the approval of uncritical data fields. | M33: 1. Create a PO. 2. Approve a PO. 3. Change multiple fields in the PO. 4. Check that workflow is only be started for changes to critical data fields. | O33: Currently setting for NB and FO --> Flexible WF will be restarted for Total Net Value change Standard fields which could be added: Header level attributes: Company Code Purchasing Group Purchasing Organization Total Net Order Value --> already selected Incoterms Currency Item level attributes: Material Group Outline Agreement Plant | P33: Medium | Q33: FIT Customizing
A34: R-3.2.33 | H34: 5.3.2 Release Purchase Order_27 | I34: Process owner | J34: I want all newly added line items in a PO to restart the approval of the entire PO | L34: so that local regulations are fulfilled. | M34: 1. Create a PO. 2. Approve a PO. 3. Add a new line item to the PO. 4. Check if the PO approval process has been started. | O34: Currently available | P34: High | Q34: FIT

Sheet 3.3
A1: Requirement ID | B1: Workstream | C1: Team | D1: Polarion # | E1: Scenario | F1: Level 1 | G1: Level 2 | H1: Level 3 | I1: I as a (persona/ WHO) | J1: want to… (WHAT) | K1: Detailed Description | L1: so that… (WHY) | M1: Acceptance Criteria | N1: Note | O1: ACN Comment | P1: Prio (DRAFT, TB FINALIZED) | Q1: Status | R1: Feature assignment | S1: using application/3rd Party Tools/interface (HOW) | T1: Value Flow Items | U1: Master Data Items | V1: SAP Best Practice | W1: SAP Module - Core | X1: SAP Module - Public Cloud | Y1: Functional Shift | Z1: Role, Rights & FIORI App relevance | AA1: Role in User Story | AB1: SAP Role Name | AC1: Siemens Role Name | AD1: SAP Transaction Code | AE1: Customizing Code/ ID | AF1: FIORI App ID | AG1: FIORI App Name | AH1: FIORI App Description | AI1: FIORI App Catalog ID | AJ1: Sandbox relevance | AK1: Sandbox relevance comment
A2: R-3.3.1 | H2: 5.3.3 Share Purchase Order with Supplier_1 | I2: Process owner | J2: I want to have the Invoice Receiver data displayed in the PO printout and EDI on header level. Email and phone number available. | K2: By default, the Requisitioner is the Invoice recipient, but the Requisitioner can change this in PR | L2: so that clarifications can be processed faster. | M2: 1. Create a PO. 2. Open a PO printout and check if technical contact is correctly dis-played. 3. Create a PO with EDI. 4. Open the EDI message and check if technical contact is correctly dis-played. | N2: 28.10-MAS: It should be in header and replace the contact person. In addition other information should be added (email + Telephone number) from the User Profile | O2: Item Level and are not a mandatory fields Requisitioner --> EBAN-AFNAM --> Item Recipient --> EBKN-WEMPF --> Account Assignment The Recipient (Invoice Receiver) will be printed on the item level. If we have many Item with Different Recipient --> Each line item will have a separate printed Recipient If the user GID has been enterred correctly and the user has an SAP User ID, then his User Name will appear in the print out | P2: High | Q2: GAP
A3: R-3.3.2 | H3: 5.3.3 Share Purchase Order with Supplier_2 | I3: Process owner | J3: I want that the invoice address is derived and displayed correctly on the PO printout and transferred in the EDI segments | L3: so that invoices coming from the supplier are addressed correctly. | M3: 1. Create PO for an EDI connected supplier. 2. Check PO printout if the invoice address is correctly displayed. 3. Check EDI message if data is in correct segments. | N3: 28.10-MAS: EDI require more analysis | O3: Invoice Address will be predefined Text and will be on header level based on Company Code Purchase Org Pgroup Doc Type | P3: High | Q3: FIT Customizing
A4: R-3.3.3 | H4: 5.3.3 Share Purchase Order with Supplier_3 | I4: Process owner | J4: I want that the correct invoice email and POC (purchase order confirmation) address are derived and displayed correctly on the PO printout and transferred cor-rectly in the EDI segments | L4: so that invoices from supplier will be addressed correctly (in case of email and POR are addressed to the desired email address). | M4: 1. Create a PO for an EDI connected supplier. 2. Check in the PO printout if both email addresses are correctly dis-played. 3. Check EDI message if data is in the correct segments. | O4: Pre-defined Text: The correct email address will be determined based on Company Code Purchasing Org Purchasing Group Order Type Correction is a configuration task, PO header texts could be use to print additional information. | P4: High | Q4: FIT Customizing
A5: R-3.3.4 | H5: 5.3.3 Share Purchase Order with Supplier_4 | I5: Process owner | J5: I want that for all countries where tax rates is required in the PO, tax rates are correctly determined | L5: so that tax regulations apply. | M5: 1. Create PO for a tax relevant country. 2. Check PO, PO printout and EDI message if tax rates are correct determined. | N5: Tax Team - Max Roesch N/A for DE CoCo | O5: Tax determination will be followed based on the Finance configuration | Q5: N/A
A6: R-3.3.5 | H6: 5.3.3 Share Purchase Order with Supplier_5 | I6: Process owner | J6: I want that for all countries where withholding tax is required in the PO that withholding tax is correctly determined | L6: so that tax regulations apply. | M6: 1. Create PO for a tax relevant country. 2. Check withholding tax in PO. | N6: Refer to new WHT Standard SX Process for Rel 1320.WHT Team - Ali S. CF T | O6: Withholding tax will be followed based on the Finance configuration | P6: High | Q6: FIT Customizing
A7: R-3.3.6 | H7: 5.3.3 Share Purchase Order with Supplier_6 | I7: Process owner | J7: I want for all countries where VAT ID is required in the PO that the VAT ID is correctly determined | L7: so that tax regulations apply. | N7: Tax Team - Max Roesch N/A for DE CoCo | O7: VAT ID determination will be based on the Business Partner and will be printed in the PO printout | P7: Medium | Q7: FIT
A8: R-3.3.7 | H8: 5.3.3 Share Purchase Order with Supplier_7 | I8: Purchaser | J8: I want to have my contact data displayed on PO printout and EDI message | L8: so that the supplier can contact purchaser in case of clarifications. | M8: Create a PO and compare the PGroup data with the address of the PO printout. | O8: Purchse Order Creator --> Name and data (from User Profile) Purchasing Group --> Name and data (from configuration) Purchasing Group per each buyer will be configured | P8: High | Q8: FIT Customizing
